Workbook

Sheet Dashboard
B2: ABC Trading Limited
B3: Dhaka, Bangladesh
B4: Executive Dashboard — Key Performance Indicators
B5: For the year ended 30-Jun-2026, with comparative 30-Jun-2025 — figures auto-update from the reports below
B7: TOTAL REVENUE | F7: NET PROFIT | J7: TOTAL ASSETS | N7: TOTAL EQUITY | R7: CURRENT RATIO | V7: NET PROFIT MARGIN
B8: ='Profit & Loss'!D12 -> 658000000 | F8: ='Profit & Loss'!D32 -> 17477408 | J8: ='Balance Sheet'!D23 -> 1239477408 | N8: ='Balance Sheet'!D31 -> 702477408 | R8: =ROUND('Balance Sheet'!D21/'Balance Sheet'!D43,2) -> 1.01 | V8: =ROUND('Profit & Loss'!D32/'Profit & Loss'!D12,4) -> 0.0266
B10: Current period | F10: Current period | J10: Current period | N10: Current period | R10: FY 2025-26 | V10: FY 2025-26
B13: Chart Source Data (auto-calculated — do not edit)
B14: Metric | C14: Amount
B15: Total Revenue | C15: ='Profit & Loss'!D12 -> 658000000
B16: Gross Profit | C16: ='Profit & Loss'!D16 -> 278000000
B17: Operating Profit | C17: ='Profit & Loss'!D26 -> 57477408
B18: Net Profit | C18: ='Profit & Loss'!D32 -> 17477408
B20: Expense | C20: Amount
B21: Salaries & Wages | C21: ='Profit & Loss'!D19 -> 90000000
B22: Rent Expense | C22: ='Profit & Loss'!D20 -> 12000000
B23: Depreciation | C23: ='Profit & Loss'!D21 -> 79522592
B24: Utilities | C24: ='Profit & Loss'!D22 -> 6000000
B25: Office & Admin | C25: ='Profit & Loss'!D23 -> 33000000
B27: Item | C27: Current | D27: Prior
B28: Total Assets | C28: ='Balance Sheet'!D23 -> 1239477408 | D28: ='Balance Sheet'!E23 -> 1270000000
B29: Total Equity | C29: ='Balance Sheet'!D31 -> 702477408 | D29: ='Balance Sheet'!E31 -> 725000000
B30: Total Liabilities | C30: ='Balance Sheet'!D36+'Balance Sheet'!D43 -> 537000000 | D30: ='Balance Sheet'!E36+'Balance Sheet'!E43 -> 545000000

Sheet Read Me
B2: Automated Financial Reporting System
B3: Journal Entries In → Balance Sheet, P&L, Changes in Equity & Cash Flow Out
B5: HOW THIS WORKBOOK WORKS
B6: 1. Go to the 'Chart of Accounts' sheet and review/extend the account list for your business (add rows if needed - just make sure every new account is tagged with Category, Sub-Category and Cash Flow Class).
B7: 2. Go to 'Opening Balances' and enter the opening (brought-forward) debit or credit balance for every Balance Sheet account as at the start of the reporting period. This is normally last period's closing Balance Sheet.
B8: 3. Enter every transaction as a Journal Entry on the 'Journal Entries' sheet - Date, Account Code, Debit or Credit, Description. Each entry must balance (Total Debit = Total Credit) - Column J flags any line that doesn't.
B9: 4. That's it. 'Trial Balance', 'Balance Sheet', 'Profit & Loss', 'Changes in Equity' and 'Cash Flow Statement' all recalculate automatically from formulas - nothing else needs to be touched.
B11: COMPATIBILITY
B12: Every formula in this workbook uses functions supported natively by BOTH Microsoft Excel and Google Sheets (SUMIFS, VLOOKUP, IF, ROUND, ABS, IFERROR). To use it in Google Sheets: File > Import > Upload this .xlsx file > 'Replace spreadsheet'. No add-ons, macros or Apps Script needed.
B14: COLOR KEY
B15: Blue text = an input you type (journal entries, opening balances, account setup).
B16: Black text = a formula/calculation - do not overtype.
... B28: Cash Flow Statement - Indirect method, fully automated and tied back to the cash account.

Sheet Chart of Accounts
B2: Chart of Accounts
B3: Master list of accounts. Add new rows as needed - keep formatting consistent.
B5: Account Code | C5: Account Name | D5: Statement | E5: Category | F5: Sub-Category | G5: Normal Side | H5: Cash Flow Class | I5: Notes
B6: 1000 | C6: Property, Plant & Equipment | D6: BS | E6: Asset | F6: Non-Current Asset | G6: Debit | H6: Investing
B7: 1010 | C7: Accumulated Depreciation | D7: BS | E7: Asset | F7: Non-Current Asset | G7: Credit | H7: Non-Cash
B8: 1020 | C8: Capital Work-in-Progress | D8: BS | E8: Asset | F8: Non-Current Asset | G8: Debit | H8: Investing
B9: 1030 | C9: Long-Term Investments | D9: BS | E9: Asset | F9: Non-Current Asset | G9: Debit | H9: Investing
B10: 1100 | C10: Inventories | D10: BS | E10: Asset | F10: Current Asset | G10: Debit | H10: Operating
B11: 1110 | C11: Accounts Receivable | D11: BS | E11: Asset | F11: Current Asset | G11: Debit | H11: Operating
B12: 1120 | C12: Advances, Deposits & Prepayments | D12: BS | E12: Asset | F12: Current Asset | G12: Debit | H12: Operating
B13: 1130 | C13: Cash & Cash Equivalents | D13: BS | E13: Asset | F13: Current Asset | G13: Debit | H13: Cash
B14: 2000 | C14: Long-Term Loan | D14: BS | E14: Liability | F14: Non-Current Liability | G14: Credit | H14: Financing
B15: 2010 | C15: Deferred Tax Liability | D15: BS | E15: Liability | F15: Non-Current Liability | G15: Credit | H15: Operating
B16: 2100 | C16: Accounts Payable | D16: BS | E16: Liability | F16: Current Liability | G16: Credit | H16: Operating
B17: 2110 | C17: Accrued Expenses | D17: BS | E17: Liability | F17: Current Liability | G17: Credit | H17: Operating
... B32: 5070 | C32: Tax Expense | D32: PL | E32: Expense | F32: Tax | G32: Debit | H32: Operating

Sheet Opening Balances
B2: Opening Balances
B3: Enter the brought-forward balance for every Balance Sheet account as at the first day of the period (usually last period's closing figures). Only ONE of Opening Debit / Opening Credit should be filled per row.
B5: Account Code | C5: Account Name | D5: Opening Debit | E5: Opening Credit | F5: Notes
B6: ='Chart of Accounts'!B6 -> 1000 | C6: ='Chart of Accounts'!C6 -> Property, Plant & Equipment | D6: 800000000 | E6: 0
B7: ='Chart of Accounts'!B7 -> 1010 | C7: ='Chart of Accounts'!C7 -> Accumulated Depreciation | D7: 0 | E7: 0
B8: ='Chart of Accounts'!B8 -> 1020 | C8: ='Chart of Accounts'!C8 -> Capital Work-in-Progress | D8: 50000000 | E8: 0
B9: ='Chart of Accounts'!B9 -> 1030 | C9: ='Chart of Accounts'!C9 -> Long-Term Investments | D9: 20000000 | E9: 0
B10: ='Chart of Accounts'!B10 -> 1100 | C10: ='Chart of Accounts'!C10 -> Inventories | D10: 120000000 | E10: 0
B11: ='Chart of Accounts'!B11 -> 1110 | C11: ='Chart of Accounts'!C11 -> Accounts Receivable | D11: 180000000 | E11: 0
B12: ='Chart of Accounts'!B12 -> 1120 | C12: ='Chart of Accounts'!C12 -> Advances, Deposits & Prepayments | D12: 40000000 | E12: 0
B13: ='Chart of Accounts'!B13 -> 1130 | C13: ='Chart of Accounts'!C13 -> Cash & Cash Equivalents | D13: 60000000 | E13: 0
B14: ='Chart of Accounts'!B14 -> 2000 | C14: ='Chart of Accounts'!C14 -> Long-Term Loan | D14: 0 | E14: 300000000
B15: ='Chart of Accounts'!B15 -> 2010 | C15: ='Chart of Accounts'!C15 -> Deferred Tax Liability | D15: 0 | E15: 10000000
B16: ='Chart of Accounts'!B16 -> 2100 | C16: ='Chart of Accounts'!C16 -> Accounts Payable | D16: 0 | E16: 150000000
B17: ='Chart of Accounts'!B17 -> 2110 | C17: ='Chart of Accounts'!C17 -> Accrued Expenses | D17: 0 | E17: 30000000
... B22: ='Chart of Accounts'!B22 -> 3020 | C22: ='Chart of Accounts'!C22 -> Revaluation Reserve | D22: 0 | E22: 50000000
B24: Control check - Opening Debits must equal Opening Credits: | E24: =IF(ROUND(SUM(D6:D22)-SUM(E6:E22),2)=0,"TRUE","CHECK!") -> TRUE

Sheet Journal Entries
B2: Journal Entries
B3: Enter every transaction here - one row per debit or credit line. Every voucher must balance (sum of its debit lines = sum of its credit lines). Pick the Account Code from the dropdown; the account name fills in automatically.
B5: Date | C5: Voucher No. | D5: Account Code | E5: Account Name | F5: Description | G5: Debit | H5: Credit | I5: Line Balanced?
B6: 45848 | C6: JV-001 | D6: 1110 | E6: =IFERROR(VLOOKUP(D6,'Chart of Accounts'!$C$6:$D$32,2,FALSE()),"") | F6: Credit sales for the period | G6: 500000000 | I6: =IF(F6>0,"Dr",IF(G6>0,"Cr","")) -> Dr
B7: 45848 | C7: JV-001 | D7: 4000 | E7: =IFERROR(VLOOKUP(D7,'Chart of Accounts'!$C$6:$D$32,2,FALSE()),"") | F7: Credit sales for the period | H7: 500000000 | I7: =IF(F7>0,"Dr",IF(G7>0,"Cr","")) -> Dr
B8: 45853 | C8: JV-002 | D8: 1130 | E8: =IFERROR(VLOOKUP(D8,'Chart of Accounts'!$C$6:$D$32,2,FALSE()),"") | F8: Cash sales for the period | G8: 150000000 | I8: =IF(F8>0,"Dr",IF(G8>0,"Cr","")) -> Dr
B9: 45853 | C9: JV-002 | D9: 4000 | E9: =IFERROR(VLOOKUP(D9,'Chart of Accounts'!$C$6:$D$32,2,FALSE()),"") | F9: Cash sales for the period | H9: 150000000 | I9: =IF(F9>0,"Dr",IF(G9>0,"Cr","")) -> Dr
B10: 45869 | C10: JV-003 | D10: 5000 | E10: =IFERROR(VLOOKUP(D10,'Chart of Accounts'!$C$6:$D$32,2,FALSE()),"") | F10: Cost of goods sold recognised | G10: 380000000 | I10: =IF(F10>0,"Dr",IF(G10>0,"Cr","")) -> Dr
B11: 45869 | C11: JV-003 | D11: 1100 | E11: =IFERROR(VLOOKUP(D11,'Chart of Accounts'!$C$6:$D$32,2,FALSE()),"") | F11: Cost of goods sold recognised | H11: 380000000 | I11: =IF(F11>0,"Dr",IF(G11>0,"Cr","")) -> Dr
B12: 45874 | C12: JV-004 | D12: 1100 | E12: =IFERROR(VLOOKUP(D12,'Chart of Accounts'!$C$6:$D$32,2,FALSE()),"") | F12: Inventory purchased on credit | G12: 300000000 | I12: =IF(F12>0,"Dr",IF(G12>0,"Cr","")) -> Dr
B13: 45874 | C13: JV-004 | D13: 2100 | E13: =IFERROR(VLOOKUP(D13,'Chart of Accounts'!$C$6:$D$32,2,FALSE()),"") | F13: Inventory purchased on credit | H13: 300000000 | I13: =IF(F13>0,"Dr",IF(G13>0,"Cr","")) -> Dr
B14: 45889 | C14: JV-005 | D14: 1130 | E14: =IFERROR(VLOOKUP(D14,'Chart of Accounts'!$C$6:$D$32,2,FALSE()),"") | F14: Cash collected from customers | G14: 450000000 | I14: =IF(F14>0,"Dr",IF(G14>0,"Cr","")) -> Dr
B15: 45889 | C15: JV-005 | D15: 1110 | E15: =IFERROR(VLOOKUP(D15,'Chart of Accounts'!$C$6:$D$32,2,FALSE()),"") | F15: Cash collected from customers | H15: 450000000 | I15: =IF(F15>0,"Dr",IF(G15>0,"Cr","")) -> Dr
B16: 45901 | C16: JV-006 | D16: 2100 | E16: =IFERROR(VLOOKUP(D16,'Chart of Accounts'!$C$6:$D$32,2,FALSE()),"") | F16: Payment to suppliers | G16: 250000000 | I16: =IF(F16>0,"Dr",IF(G16>0,"Cr","")) -> Dr
B17: 45901 | C17: JV-006 | D17: 1130 | E17: =IFERROR(VLOOKUP(D17,'Chart of Accounts'!$C$6:$D$32,2,FALSE()),"") | F17: Payment to suppliers | H17: 250000000 | I17: =IF(F17>0,"Dr",IF(G17>0,"Cr","")) -> Dr
B18: 45930 | C18: JV-007 | D18: 5010 | E18: =IFERROR(VLOOKUP(D18,'Chart of Accounts'!$C$6:$D$32,2,FALSE()),"") | F18: Staff salaries paid | G18: 90000000 | I18: =IF(F18>0,"Dr",IF(G18>0,"Cr","")) -> Dr
B19: 45930 | C19: JV-007 | D19: 1130 | E19: =IFERROR(VLOOKUP(D19,'Chart of Accounts'!$C$6:$D$32,2,FALSE()),"") | F19: Staff salaries paid | H19: 90000000 | I19: =IF(F19>0,"Dr",IF(G19>0,"Cr","")) -> Dr
B20: 45930 | C20: JV-008 | D20: 5020 | E20: =IFERROR(VLOOKUP(D20,'Chart of Accounts'!$C$6:$D$32,2,FALSE()),"") | F20: Office rent paid | G20: 12000000 | I20: =IF(F20>0,"Dr",IF(G20>0,"Cr","")) -> Dr
B21: 45930 | C21: JV-008 | D21: 1130 | E21: =IFERROR(VLOOKUP(D21,'Chart of Accounts'!$C$6:$D$32,2,FALSE()),"") | F21: Office rent paid | H21: 12000000 | I21: =IF(F21>0,"Dr",IF(G21>0,"Cr","")) -> Dr
B22: 45935 | C22: JV-009 | D22: 5040 | E22: =IFERROR(VLOOKUP(D22,'Chart of Accounts'!$C$6:$D$32,2,FALSE()),"") | F22: Utility bills paid | G22: 6000000 | I22: =IF(F22>0,"Dr",IF(G22>0,"Cr","")) -> Dr
B23: 45935 | C23: JV-009 | D23: 1130 | E23: =IFERROR(VLOOKUP(D23,'Chart of Accounts'!$C$6:$D$32,2,FALSE()),"") | F23: Utility bills paid | H23: 6000000 | I23: =IF(F23>0,"Dr",IF(G23>0,"Cr","")) -> Dr
B24: 45940 | C24: JV-010 | D24: 5050 | E24: =IFERROR(VLOOKUP(D24,'Chart of Accounts'!$C$6:$D$32,2,FALSE()),"") | F24: Office & admin expenses paid | G24: 18000000 | I24: =IF(F24>0,"Dr",IF(G24>0,"Cr","")) -> Dr
B25: 45940 | C25: JV-010 | D25: 1130 | E25: =IFERROR(VLOOKUP(D25,'Chart of Accounts'!$C$6:$D$32,2,FALSE()),"") | F25: Office & admin expenses paid | H25: 18000000 | I25: =IF(F25>0,"Dr",IF(G25>0,"Cr","")) -> Dr
B26: 45961 | C26: JV-011 | D26: 1000 | E26: =IFERROR(VLOOKUP(D26,'Chart of Accounts'!$C$6:$D$32,2,FALSE()),"") | F26: Purchase of new equipment | G26: 85000000 | I26: =IF(F26>0,"Dr",IF(G26>0,"Cr","")) -> Dr
B27: 45961 | C27: JV-011 | D27: 1130 | E27: =IFERROR(VLOOKUP(D27,'Chart of Accounts'!$C$6:$D$32,2,FALSE()),"") | F27: Purchase of new equipment | H27: 85000000 | I27: =IF(F27>0,"Dr",IF(G27>0,"Cr","")) -> Dr
B28: 45966 | C28: JV-012 | D28: 1020 | E28: =IFERROR(VLOOKUP(D28,'Chart of Accounts'!$C$6:$D$32,2,FALSE()),"") | F28: Capital work-in-progress - new branch fit-out | G28: 40000000 | I28: =IF(F28>0,"Dr",IF(G28>0,"Cr","")) -> Dr
B29: 45966 | C29: JV-012 | D29: 1130 | E29: =IFERROR(VLOOKUP(D29,'Chart of Accounts'!$C$6:$D$32,2,FALSE()),"") | F29: Capital work-in-progress - new branch fit-out | H29: 40000000 | I29: =IF(F29>0,"Dr",IF(G29>0,"Cr","")) -> Dr
B30: 45981 | C30: JV-013 | D30: 1130 | E30: =IFERROR(VLOOKUP(D30,'Chart of Accounts'!$C$6:$D$32,2,FALSE()),"") | F30: Other income received | G30: 8000000 | I30: =IF(F30>0,"Dr",IF(G30>0,"Cr","")) -> Dr
B31: 45981 | C31: JV-013 | D31: 4010 | E31: =IFERROR(VLOOKUP(D31,'Chart of Accounts'!$C$6:$D$32,2,FALSE()),"") | F31: Other income received | H31: 8000000 | I31: =IF(F31>0,"Dr",IF(G31>0,"Cr","")) -> Dr
B32: 45992 | C32: JV-014 | D32: 5060 | E32: =IFERROR(VLOOKUP(D32,'Chart of Accounts'!$C$6:$D$32,2,FALSE()),"") | F32: Interest paid on term loan | G32: 25000000 | I32: =IF(F32>0,"Dr",IF(G32>0,"Cr","")) -> Dr
B33: 45992 | C33: JV-014 | D33: 1130 | E33: =IFERROR(VLOOKUP(D33,'Chart of Accounts'!$C$6:$D$32,2,FALSE()),"") | F33: Interest paid on term loan | H33: 25000000 | I33: =IF(F33>0,"Dr",IF(G33>0,"Cr","")) -> Dr
B34: 46006 | C34: JV-015 | D34: 2000 | E34: =IFERROR(VLOOKUP(D34,'Chart of Accounts'!$C$6:$D$32,2,FALSE()),"") | F34: Repayment of long-term loan | G34: 100000000 | I34: =IF(F34>0,"Dr",IF(G34>0,"Cr","")) -> Dr
B35: 46006 | C35: JV-015 | D35: 1130 | E35: =IFERROR(VLOOKUP(D35,'Chart of Accounts'!$C$6:$D$32,2,FALSE()),"") | F35: Repayment of long-term loan | H35: 100000000 | I35: =IF(F35>0,"Dr",IF(G35>0,"Cr","")) -> Dr
B36: 46032 | C36: JV-016 | D36: 1130 | E36: =IFERROR(VLOOKUP(D36,'Chart of Accounts'!$C$6:$D$32,2,FALSE()),"") | F36: Short-term loan drawn down | G36: 20000000 | I36: =IF(F36>0,"Dr",IF(G36>0,"Cr","")) -> Dr
B37: 46032 | C37: JV-016 | D37: 2120 | E37: =IFERROR(VLOOKUP(D37,'Chart of Accounts'!$C$6:$D$32,2,FALSE()),"") | F37: Short-term loan drawn down | H37: 20000000 | I37: =IF(F37>0,"Dr",IF(G37>0,"Cr","")) -> Dr
B38: 46042 | C38: JV-017 | D38: 1120 | E38: =IFERROR(VLOOKUP(D38,'Chart of Accounts'!$C$6:$D$32,2,FALSE()),"") | F38: Advance paid to landlord/suppliers | G38: 25000000 | I38: =IF(F38>0,"Dr",IF(G38>0,"Cr","")) -> Dr
B39: 46042 | C39: JV-017 | D39: 1130 | E39: =IFERROR(VLOOKUP(D39,'Chart of Accounts'!$C$6:$D$32,2,FALSE()),"") | F39: Advance paid to landlord/suppliers | H39: 25000000 | I39: =IF(F39>0,"Dr",IF(G39>0,"Cr","")) -> Dr
B40: 46063 | C40: JV-018 | D40: 5050 | E40: =IFERROR(VLOOKUP(D40,'Chart of Accounts'!$C$6:$D$32,2,FALSE()),"") | F40: Admin expenses accrued (unpaid) | G40: 15000000 | I40: =IF(F40>0,"Dr",IF(G40>0,"Cr","")) -> Dr
B41: 46063 | C41: JV-018 | D41: 2110 | E41: =IFERROR(VLOOKUP(D41,'Chart of Accounts'!$C$6:$D$32,2,FALSE()),"") | F41: Admin expenses accrued (unpaid) | H41: 15000000 | I41: =IF(F41>0,"Dr",IF(G41>0,"Cr","")) -> Dr
B42: 46082 | C42: JV-019 | D42: 1130 | E42: =IFERROR(VLOOKUP(D42,'Chart of Accounts'!$C$6:$D$32,2,FALSE()),"") | F42: Fresh share capital issued for cash | G42: 10000000 | I42: =IF(F42>0,"Dr",IF(G42>0,"Cr","")) -> Dr
...

Sheet Trial Balance
B2: Trial Balance
B3: Fully automated - do not type into this sheet. Opening + Period Movement = Closing, for every account.
B5: Code | C5: Account Name | D5: Stmt | E5: Sub-Category | F5: CF Class | G5: Opening Dr | H5: Opening Cr | I5: Period Dr | J5: Period Cr | K5: Closing Dr | L5: Closing Cr
B6: ='Chart of Accounts'!B6 -> 1000 | C6: ='Chart of Accounts'!C6 -> Property, Plant & Equipment | D6: ='Chart of Accounts'!D6 -> BS | E6: ='Chart of Accounts'!E6 -> Asset | F6: ='Chart of Accounts'!H6 -> Investing | G6: =IFERROR(SUMIF('Opening Balances'!$B$6:$B$22,B6,'Opening Balances'!$D$6:$D$22),0) -> 800000000 | H6: =IFERROR(SUMIF('Opening Balances'!$B$6:$B$22,B6,'Opening Balances'!$E$6:$E$22),0) -> 0 | I6: =SUMIFS('Journal Entries'!$G$6:$G$55,'Journal Entries'!$D$6:$D$55,B6) -> 85000000 | J6: =SUMIFS('Journal Entries'!$H$6:$H$55,'Journal Entries'!$D$6:$D$55,B6) -> 0 | K6: =MAX((G6-H6)+(I6-J6),0) -> 885000000 | L6: =MAX(-((G6-H6)+(I6-J6)),0) -> 0
B7: ='Chart of Accounts'!B7 -> 1010 | C7: ='Chart of Accounts'!C7 -> Accumulated Depreciation | D7: ='Chart of Accounts'!D7 -> BS | E7: ='Chart of Accounts'!E7 -> Asset | F7: ='Chart of Accounts'!H7 -> Non-Cash | G7: =IFERROR(SUMIF('Opening Balances'!$B$6:$B$22,B7,'Opening Balances'!$D$6:$D$22),0) -> 0 | H7: =IFERROR(SUMIF('Opening Balances'!$B$6:$B$22,B7,'Opening Balances'!$E$6:$E$22),0) -> 0 | I7: =SUMIFS('Journal Entries'!$G$6:$G$55,'Journal Entries'!$D$6:$D$55,B7) -> 0 | J7: =SUMIFS('Journal Entries'!$H$6:$H$55,'Journal Entries'!$D$6:$D$55,B7) -> 79522592 | K7: =MAX((G7-H7)+(I7-J7),0) -> 0 | L7: =MAX(-((G7-H7)+(I7-J7)),0) -> 79522592
B8: ='Chart of Accounts'!B8 -> 1020 | C8: ='Chart of Accounts'!C8 -> Capital Work-in-Progress | D8: ='Chart of Accounts'!D8 -> BS | E8: ='Chart of Accounts'!E8 -> Asset | F8: ='Chart of Accounts'!H8 -> Investing | G8: =IFERROR(SUMIF('Opening Balances'!$B$6:$B$22,B8,'Opening Balances'!$D$6:$D$22),0) -> 50000000 | H8: =IFERROR(SUMIF('Opening Balances'!$B$6:$B$22,B8,'Opening Balances'!$E$6:$E$22),0) -> 0 | I8: =SUMIFS('Journal Entries'!$G$6:$G$55,'Journal Entries'!$D$6:$D$55,B8) -> 40000000 | J8: =SUMIFS('Journal Entries'!$H$6:$H$55,'Journal Entries'!$D$6:$D$55,B8) -> 0 | K8: =MAX((G8-H8)+(I8-J8),0) -> 90000000 | L8: =MAX(-((G8-H8)+(I8-J8)),0) -> 0
B9: ='Chart of Accounts'!B9 -> 1030 | C9: ='Chart of Accounts'!C9 -> Long-Term Investments | D9: ='Chart of Accounts'!D9 -> BS | E9: ='Chart of Accounts'!E9 -> Asset | F9: ='Chart of Accounts'!H9 -> Investing | G9: =IFERROR(SUMIF('Opening Balances'!$B$6:$B$22,B9,'Opening Balances'!$D$6:$D$22),0) -> 20000000 | H9: =IFERROR(SUMIF('Opening Balances'!$B$6:$B$22,B9,'Opening Balances'!$E$6:$E$22),0) -> 0 | I9: =SUMIFS('Journal Entries'!$G$6:$G$55,'Journal Entries'!$D$6:$D$55,B9) -> 0 | J9: =SUMIFS('Journal Entries'!$H$6:$H$55,'Journal Entries'!$D$6:$D$55,B9) -> 0 | K9: =MAX((G9-H9)+(I9-J9),0) -> 20000000 | L9: =MAX(-((G9-H9)+(I9-J9)),0) -> 0
B10: ='Chart of Accounts'!B10 -> 1100 | C10: ='Chart of Accounts'!C10 -> Inventories | D10: ='Chart of Accounts'!D10 -> BS | E10: ='Chart of Accounts'!E10 -> Asset | F10: ='Chart of Accounts'!H10 -> Operating | G10: =IFERROR(SUMIF('Opening Balances'!$B$6:$B$22,B10,'Opening Balances'!$D$6:$D$22),0) -> 120000000 | H10: =IFERROR(SUMIF('Opening Balances'!$B$6:$B$22,B10,'Opening Balances'!$E$6:$E$22),0) -> 0 | I10: =SUMIFS('Journal Entries'!$G$6:$G$55,'Journal Entries'!$D$6:$D$55,B10) -> 300000000 | J10: =SUMIFS('Journal Entries'!$H$6:$H$55,'Journal Entries'!$D$6:$D$55,B10) -> 380000000 | K10: =MAX((G10-H10)+(I10-J10),0) -> 40000000 | L10: =MAX(-((G10-H10)+(I10-J10)),0) -> 0
B11: ='Chart of Accounts'!B11 -> 1110 | C11: ='Chart of Accounts'!C11 -> Accounts Receivable | D11: ='Chart of Accounts'!D11 -> BS | E11: ='Chart of Accounts'!E11 -> Asset | F11: ='Chart of Accounts'!H11 -> Operating | G11: =IFERROR(SUMIF('Opening Balances'!$B$6:$B$22,B11,'Opening Balances'!$D$6:$D$22),0) -> 180000000 | H11: =IFERROR(SUMIF('Opening Balances'!$B$6:$B$22,B11,'Opening Balances'!$E$6:$E$22),0) -> 0 | I11: =SUMIFS('Journal Entries'!$G$6:$G$55,'Journal Entries'!$D$6:$D$55,B11) -> 500000000 | J11: =SUMIFS('Journal Entries'!$H$6:$H$55,'Journal Entries'!$D$6:$D$55,B11) -> 600000000 | K11: =MAX((G11-H11)+(I11-J11),0) -> 80000000 | L11: =MAX(-((G11-H11)+(I11-J11)),0) -> 0
B12: ='Chart of Accounts'!B12 -> 1120 | C12: ='Chart of Accounts'!C12 -> Advances, Deposits & Prepayments | D12: ='Chart of Accounts'!D12 -> BS | E12: ='Chart of Accounts'!E12 -> Asset | F12: ='Chart of Accounts'!H12 -> Operating | G12: =IFERROR(SUMIF('Opening Balances'!$B$6:$B$22,B12,'Opening Balances'!$D$6:$D$22),0) -> 40000000 | H12: =IFERROR(SUMIF('Opening Balances'!$B$6:$B$22,B12,'Opening Balances'!$E$6:$E$22),0) -> 0 | I12: =SUMIFS('Journal Entries'!$G$6:$G$55,'Journal Entries'!$D$6:$D$55,B12) -> 25000000 | J12: =SUMIFS('Journal Entries'!$H$6:$H$55,'Journal Entries'!$D$6:$D$55,B12) -> 0 | K12: =MAX((G12-H12)+(I12-J12),0) -> 65000000 | L12: =MAX(-((G12-H12)+(I12-J12)),0) -> 0
B13: ='Chart of Accounts'!B13 -> 1130 | C13: ='Chart of Accounts'!C13 -> Cash & Cash Equivalents | D13: ='Chart of Accounts'!D13 -> BS | E13: ='Chart of Accounts'!E13 -> Asset | F13: ='Chart of Accounts'!H13 -> Cash | G13: =IFERROR(SUMIF('Opening Balances'!$B$6:$B$22,B13,'Opening Balances'!$D$6:$D$22),0) -> 60000000 | H13: =IFERROR(SUMIF('Opening Balances'!$B$6:$B$22,B13,'Opening Balances'!$E$6:$E$22),0) -> 0 | I13: =SUMIFS('Journal Entries'!$G$6:$G$55,'Journal Entries'!$D$6:$D$55,B13) -> 788000000 | J13: =SUMIFS('Journal Entries'!$H$6:$H$55,'Journal Entries'!$D$6:$D$55,B13) -> 709000000 | K13: =MAX((G13-H13)+(I13-J13),0) -> 139000000 | L13: =MAX(-((G13-H13)+(I13-J13)),0) -> 0
B14: ='Chart of Accounts'!B14 -> 2000 | C14: ='Chart of Accounts'!C14 -> Long-Term Loan | D14: ='Chart of Accounts'!D14 -> BS | E14: ='Chart of Accounts'!E14 -> Liability | F14: ='Chart of Accounts'!H14 -> Financing | G14: =IFERROR(SUMIF('Opening Balances'!$B$6:$B$22,B14,'Opening Balances'!$D$6:$D$22),0) -> 0 | H14: =IFERROR(SUMIF('Opening Balances'!$B$6:$B$22,B14,'Opening Balances'!$E$6:$E$22),0) -> 300000000 | I14: =SUMIFS('Journal Entries'!$G$6:$G$55,'Journal Entries'!$D$6:$D$55,B14) -> 100000000 | J14: =SUMIFS('Journal Entries'!$H$6:$H$55,'Journal Entries'!$D$6:$D$55,B14) -> 0 | K14: =MAX((G14-H14)+(I14-J14),0) -> 0 | L14: =MAX(-((G14-H14)+(I14-J14)),0) -> 200000000
B15: ='Chart of Accounts'!B15 -> 2010 | C15: ='Chart of Accounts'!C15 -> Deferred Tax Liability | D15: ='Chart of Accounts'!D15 -> BS | E15: ='Chart of Accounts'!E15 -> Liability | F15: ='Chart of Accounts'!H15 -> Operating | G15: =IFERROR(SUMIF('Opening Balances'!$B$6:$B$22,B15,'Opening Balances'!$D$6:$D$22),0) -> 0 | H15: =IFERROR(SUMIF('Opening Balances'!$B$6:$B$22,B15,'Opening Balances'!$E$6:$E$22),0) -> 10000000 | I15: =SUMIFS('Journal Entries'!$G$6:$G$55,'Journal Entries'!$D$6:$D$55,B15) -> 0 | J15: =SUMIFS('Journal Entries'!$H$6:$H$55,'Journal Entries'!$D$6:$D$55,B15) -> 5000000 | K15: =MAX((G15-H15)+(I15-J15),0) -> 0 | L15: =MAX(-((G15-H15)+(I15-J15)),0) -> 15000000
B16: ='Chart of Accounts'!B16 -> 2100 | C16: ='Chart of Accounts'!C16 -> Accounts Payable | D16: ='Chart of Accounts'!D16 -> BS | E16: ='Chart of Accounts'!E16 -> Liability | F16: ='Chart of Accounts'!H16 -> Operating | G16: =IFERROR(SUMIF('Opening Balances'!$B$6:$B$22,B16,'Opening Balances'!$D$6:$D$22),0) -> 0 | H16: =IFERROR(SUMIF('Opening Balances'!$B$6:$B$22,B16,'Opening Balances'!$E$6:$E$22),0) -> 150000000 | I16: =SUMIFS('Journal Entries'!$G$6:$G$55,'Journal Entries'!$D$6:$D$55,B16) -> 250000000 | J16: =SUMIFS('Journal Entries'!$H$6:$H$55,'Journal Entries'!$D$6:$D$55,B16) -> 300000000 | K16: =MAX((G16-H16)+(I16-J16),0) -> 0 | L16: =MAX(-((G16-H16)+(I16-J16)),0) -> 200000000
B17: ='Chart of Accounts'!B17 -> 2110 | C17: ='Chart of Accounts'!C17 -> Accrued Expenses | D17: ='Chart of Accounts'!D17 -> BS | E17: ='Chart of Accounts'!E17 -> Liability | F17: ='Chart of Accounts'!H17 -> Operating | G17: =IFERROR(SUMIF('Opening Balances'!$B$6:$B$22,B17,'Opening Balances'!$D$6:$D$22),0) -> 0 | H17: =IFERROR(SUMIF('Opening Balances'!$B$6:$B$22,B17,'Opening Balances'!$E$6:$E$22),0) -> 30000000 | I17: =SUMIFS('Journal Entries'!$G$6:$G$55,'Journal Entries'!$D$6:$D$55,B17) -> 0 | J17: =SUMIFS('Journal Entries'!$H$6:$H$55,'Journal Entries'!$D$6:$D$55,B17) -> 15000000 | K17: =MAX((G17-H17)+(I17-J17),0) -> 0 | L17: =MAX(-((G17-H17)+(I17-J17)),0) -> 45000000
... B32: ='Chart of Accounts'!B32 -> 5070 | C32: ='Chart of Accounts'!C32 -> Tax Expense | D32: ='Chart of Accounts'!D32 -> PL | E32: ='Chart of Accounts'!E32 -> Expense | F32: ='Chart of Accounts'!H32 -> Operating | G32: =IFERROR(SUMIF('Opening Balances'!$B$6:$B$22,B32,'Opening Balances'!$D$6:$D$22),0) -> 0 | H32: =IFERROR(SUMIF('Opening Balances'!$B$6:$B$22,B32,'Opening Balances'!$E$6:$E$22),0) -> 0 | I32: =SUMIFS('Journal Entries'!$G$6:$G$55,'Journal Entries'!$D$6:$D$55,B32) -> 15000000 | J32: =SUMIFS('Journal Entries'!$H$6:$H$55,'Journal Entries'!$D$6:$D$55,B32) -> 0 | K32: =MAX((G32-H32)+(I32-J32),0) -> 15000000 | L32: =MAX(-((G32-H32)+(I32-J32)),0) -> 0
C33: TOTAL | G33: =SUM(G6:G32) -> 1270000000 | H33: =SUM(H6:H32) -> 1270000000 | I33: =SUM(I6:I32) -> 2786522592 | J33: =SUM(J6:J32) -> 2786522592 | K33: =SUM(K6:K32) -> 1959522592 | L33: =SUM(L6:L32) -> 1959522592
C34: Control check - Closing Debits = Closing Credits: | K34: =IF(ROUND(K33-L33,2)=0,"TRUE","CHECK!") -> TRUE

Sheet Balance Sheet
B2: ABC Trading Limited
B3: Dhaka, Bangladesh
B4: Statement of Financial Position
B5: As at 30-Jun-2026, with comparative 30-Jun-2025
B7: Particulars | C7: Notes | D7: 30-Jun-2026 (Current) | E7: 30-Jun-2025 (Prior)
B9: ASSETS
B10: Non-Current Assets
B11: Property, Plant & Equipment (net) | C11: 1 | D11: =('Trial Balance'!$K$6-'Trial Balance'!$L$6)-('Trial Balance'!$L$7-'Trial Balance'!$K$7) -> 805477408 | E11: =(IFERROR(SUMIF('Opening Balances'!$B$6:$B$22,1000,'Opening Balances'!$D$6:$D$22)-SUMIF('Opening Balances'!$B$6:$B$22,1000,'Opening Balances'!$E$6:$E$22),0))-(IFERROR(SUMIF('Opening Balances'!$B$6:$B$22,1010,'Opening Balances'!$E$6:$E$22)-SUMIF('Opening Balances'!$B$6:$B$22,1010,'Opening Balances'!$D$6:$D$22),0)) -> 800000000
B12: Capital Work-in-Progress | C12: 2 | D12: =('Trial Balance'!$K$8-'Trial Balance'!$L$8) -> 90000000 | E12: =IFERROR(SUMIF('Opening Balances'!$B$6:$B$22,1020,'Opening Balances'!$D$6:$D$22)-SUMIF('Opening Balances'!$B$6:$B$22,1020,'Opening Balances'!$E$6:$E$22),0) -> 50000000
B13: Long-Term Investments | C13: 3 | D13: =('Trial Balance'!$K$9-'Trial Balance'!$L$9) -> 20000000 | E13: =IFERROR(SUMIF('Opening Balances'!$B$6:$B$22,1030,'Opening Balances'!$D$6:$D$22)-SUMIF('Opening Balances'!$B$6:$B$22,1030,'Opening Balances'!$E$6:$E$22),0) -> 20000000
B14: Total Non-Current Assets | D14: =SUM(D11:D13) -> 915477408 | E14: =SUM(E11:E13) -> 870000000
B16: Current Assets
B17: Inventories | C17: 4 | D17: =('Trial Balance'!$K$10-'Trial Balance'!$L$10) -> 40000000 | E17: =IFERROR(SUMIF('Opening Balances'!$B$6:$B$22,1100,'Opening Balances'!$D$6:$D$22)-SUMIF('Opening Balances'!$B$6:$B$22,1100,'Opening Balances'!$E$6:$E$22),0) -> 120000000
B18: Accounts Receivable | C18: 5 | D18: =('Trial Balance'!$K$11-'Trial Balance'!$L$11) -> 80000000 | E18: =IFERROR(SUMIF('Opening Balances'!$B$6:$B$22,1110,'Opening Balances'!$D$6:$D$22)-SUMIF('Opening Balances'!$B$6:$B$22,1110,'Opening Balances'!$E$6:$E$22),0) -> 180000000
B19: Advances, Deposits & Prepayments | C19: 6 | D19: =('Trial Balance'!$K$12-'Trial Balance'!$L$12) -> 65000000 | E19: =IFERROR(SUMIF('Opening Balances'!$B$6:$B$22,1120,'Opening Balances'!$D$6:$D$22)-SUMIF('Opening Balances'!$B$6:$B$22,1120,'Opening Balances'!$E$6:$E$22),0) -> 40000000
B20: Cash & Cash Equivalents | C20: 7 | D20: =('Trial Balance'!$K$13-'Trial Balance'!$L$13) -> 139000000 | E20: =IFERROR(SUMIF('Opening Balances'!$B$6:$B$22,1130,'Opening Balances'!$D$6:$D$22)-SUMIF('Opening Balances'!$B$6:$B$22,1130,'Opening Balances'!$E$6:$E$22),0) -> 60000000
B21: Total Current Assets | D21: =SUM(D17:D20) -> 324000000 | E21: =SUM(E17:E20) -> 400000000
B23: TOTAL ASSETS | D23: =D14+D21 -> 1239477408 | E23: =E14+E21 -> 1270000000
B26: EQUITY & LIABILITIES
B27: Equity
B28: Share Capital | C28: 8 | D28: =('Trial Balance'!$L$20-'Trial Balance'!$K$20) -> 410000000 | E28: =IFERROR(SUMIF('Opening Balances'!$B$6:$B$22,3000,'Opening Balances'!$E$6:$E$22)-SUMIF('Opening Balances'!$B$6:$B$22,3000,'Opening Balances'!$D$6:$D$22),0) -> 400000000
B29: Revaluation Reserve | C29: 9 | D29: =('Trial Balance'!$L$22-'Trial Balance'!$K$22) -> 50000000 | E29: =IFERROR(SUMIF('Opening Balances'!$B$6:$B$22,3020,'Opening Balances'!$E$6:$E$22)-SUMIF('Opening Balances'!$B$6:$B$22,3020,'Opening Balances'!$D$6:$D$22),0) -> 50000000
B30: Retained Earnings | C30: 10 | D30: =('Trial Balance'!$L$21-'Trial Balance'!$K$21)+'Profit & Loss'!$D$32 -> 242477408 | E30: =IFERROR(SUMIF('Opening Balances'!$B$6:$B$22,3010,'Opening Balances'!$E$6:$E$22)-SUMIF('Opening Balances'!$B$6:$B$22,3010,'Opening Balances'!$D$6:$D$22),0) -> 275000000
B31: Total Equity | D31: =SUM(D28:D30) -> 702477408 | E31: =SUM(E28:E30) -> 725000000
B33: Non-Current Liabilities
B34: Long-Term Loan | C34: 11 | D34: =('Trial Balance'!$L$14-'Trial Balance'!$K$14) -> 200000000 | E34: =IFERROR(SUMIF('Opening Balances'!$B$6:$B$22,2000,'Opening Balances'!$E$6:$E$22)-SUMIF('Opening Balances'!$B$6:$B$22,2000,'Opening Balances'!$D$6:$D$22),0) -> 300000000
B35: Deferred Tax Liability | C35: 12 | D35: =('Trial Balance'!$L$15-'Trial Balance'!$K$15) -> 15000000 | E35: =IFERROR(SUMIF('Opening Balances'!$B$6:$B$22,2010,'Opening Balances'!$E$6:$E$22)-SUMIF('Opening Balances'!$B$6:$B$22,2010,'Opening Balances'!$D$6:$D$22),0) -> 10000000
B36: Total Non-Current Liabilities | D36: =SUM(D34:D35) -> 215000000 | E36: =SUM(E34:E35) -> 310000000
B38: Current Liabilities
B39: Accounts Payable | C39: 13 | D39: =('Trial Balance'!$L$16-'Trial Balance'!$K$16) -> 200000000 | E39: =IFERROR(SUMIF('Opening Balances'!$B$6:$B$22,2100,'Opening Balances'!$E$6:$E$22)-SUMIF('Opening Balances'!$B$6:$B$22,2100,'Opening Balances'!$D$6:$D$22),0) -> 150000000
B40: Accrued Expenses | C40: 14 | D40: =('Trial Balance'!$L$17-'Trial Balance'!$K$17) -> 45000000 | E40: =IFERROR(SUMIF('Opening Balances'!$B$6:$B$22,2110,'Opening Balances'!$E$6:$E$22)-SUMIF('Opening Balances'!$B$6:$B$22,2110,'Opening Balances'!$D$6:$D$22),0) -> 30000000
B41: Short-Term Loan | C41: 15 | D41: =('Trial Balance'!$L$18-'Trial Balance'!$K$18) -> 60000000 | E41: =IFERROR(SUMIF('Opening Balances'!$B$6:$B$22,2120,'Opening Balances'!$E$6:$E$22)-SUMIF('Opening Balances'!$B$6:$B$22,2120,'Opening Balances'!$D$6:$D$22),0) -> 40000000
B42: Tax Payable | C42: 16 | D42: =('Trial Balance'!$L$19-'Trial Balance'!$K$19) -> 17000000 | E42: =IFERROR(SUMIF('Opening Balances'!$B$6:$B$22,2130,'Opening Balances'!$E$6:$E$22)-SUMIF('Opening Balances'!$B$6:$B$22,2130,'Opening Balances'!$D$6:$D$22),0) -> 15000000
B43: Total Current Liabilities | D43: =SUM(D39:D42) -> 322000000 | E43: =SUM(E39:E42) -> 235000000
B45: TOTAL EQUITY & LIABILITIES | D45: =D31+D36+D43 -> 1239477408 | E45: =E31+E36+E43 -> 1270000000
B48: Control check - Total Assets = Total Equity & Liabilities (Current): | D48: =IF(ROUND(D23-D45,0)=0,"TRUE","CHECK!") -> TRUE
B49: Control check - Total Assets = Total Equity & Liabilities (Prior): | D49: =IF(ROUND(E23-E45,0)=0,"TRUE","CHECK!") -> TRUE

Sheet Profit & Loss
B2: ABC Trading Limited
B3: Dhaka, Bangladesh
B4: Profit & Loss Statement (Income Statement)
B5: For the year ended 30-Jun-2026
B7: Particulars | D7: Amount (Taka)
B9: Revenue
B10: Sales Revenue | D10: ='Trial Balance'!$L$23-'Trial Balance'!$K$23 -> 650000000
B11: Other Income | D11: ='Trial Balance'!$L$24-'Trial Balance'!$K$24 -> 8000000
B12: Total Revenue | D12: =SUM(D10:D11) -> 658000000
B14: Cost of Sales
B15: Cost of Goods Sold | D15: ='Trial Balance'!$K$25-'Trial Balance'!$L$25 -> 380000000
B16: Gross Profit | D16: =D12-D15 -> 278000000
B18: Operating Expenses
B19: Salaries & Wages | D19: ='Trial Balance'!$K$26-'Trial Balance'!$L$26 -> 90000000
B20: Rent Expense | D20: ='Trial Balance'!$K$27-'Trial Balance'!$L$27 -> 12000000
B21: Depreciation Expense | D21: ='Trial Balance'!$K$28-'Trial Balance'!$L$28 -> 79522592
B22: Utilities Expense | D22: ='Trial Balance'!$K$29-'Trial Balance'!$L$29 -> 6000000
B23: Office & Admin Expense | D23: ='Trial Balance'!$K$30-'Trial Balance'!$L$30 -> 33000000
B24: Total Operating Expenses | D24: =SUM(D19:D23) -> 220522592
B26: Operating Profit | D26: =D16-D24 -> 57477408
B28: Interest / Finance Cost | D28: ='Trial Balance'!$K$31-'Trial Balance'!$L$31 -> 25000000
B29: Profit Before Tax | D29: =D26-D28 -> 32477408
B31: Tax Expense (current + deferred) | D31: ='Trial Balance'!$K$32-'Trial Balance'!$L$32 -> 15000000
B32: Net Profit for the Period | D32: =D29-D31 -> 17477408
B35: Net Profit for the Period flows automatically into Retained Earnings on the Balance Sheet and Changes in Equity statement.

Sheet Changes in Equity
B2: ABC Trading Limited
B3: Dhaka, Bangladesh
B4: Statement of Changes in Equity
B5: For the year ended 30-Jun-2026
B7: Particulars | C7: Share Capital | D7: Revaluation Reserve | E7: Retained Earnings | F7: Total Equity
B8: Balance at 1 Jul 2025 (Opening) | C8: =IFERROR(SUMIF('Opening Balances'!$B$6:$B$22,3000,'Opening Balances'!$E$6:$E$22)-SUMIF('Opening Balances'!$B$6:$B$22,3000,'Opening Balances'!$D$6:$D$22),0) -> 400000000 | D8: =IFERROR(SUMIF('Opening Balances'!$B$6:$B$22,3020,'Opening Balances'!$E$6:$E$22)-SUMIF('Opening Balances'!$B$6:$B$22,3020,'Opening Balances'!$D$6:$D$22),0) -> 50000000 | E8: =IFERROR(SUMIF('Opening Balances'!$B$6:$B$22,3010,'Opening Balances'!$E$6:$E$22)-SUMIF('Opening Balances'!$B$6:$B$22,3010,'Opening Balances'!$D$6:$D$22),0) -> 275000000 | F8: =C8+D8+E8 -> 725000000
B9: Shares issued during the period | C9: =('Trial Balance'!$L$20-'Trial Balance'!$K$20)-IFERROR(SUMIF('Opening Balances'!$B$6:$B$22,3000,'Opening Balances'!$E$6:$E$22)-SUMIF('Opening Balances'!$B$6:$B$22,3000,'Opening Balances'!$D$6:$D$22),0) -> 10000000 | D9: 0 | E9: 0 | F9: =C9+D9+E9 -> 10000000
B10: Net profit for the period | C10: 0 | D10: 0 | E10: ='Profit & Loss'!$D$32 -> 17477408 | F10: =C10+D10+E10 -> 17477408
B11: Dividends declared / paid | C11: 0 | D11: 0 | E11: =('Trial Balance'!$L$21-'Trial Balance'!$K$21)-IFERROR(SUMIF('Opening Balances'!$B$6:$B$22,3010,'Opening Balances'!$E$6:$E$22)-SUMIF('Opening Balances'!$B$6:$B$22,3010,'Opening Balances'!$D$6:$D$22),0) -> -50000000 | F11: =C11+D11+E11 -> -50000000
B12: Revaluation movement during the period | C12: 0 | D12: =('Trial Balance'!$L$22-'Trial Balance'!$K$22)-IFERROR(SUMIF('Opening Balances'!$B$6:$B$22,3020,'Opening Balances'!$E$6:$E$22)-SUMIF('Opening Balances'!$B$6:$B$22,3020,'Opening Balances'!$D$6:$D$22),0) -> 0 | E12: 0 | F12: =C12+D12+E12 -> 0
B13: Balance at 30 Jun 2026 (Closing) | C13: =SUM(C8:C12) -> 410000000 | D13: =SUM(D8:D12) -> 50000000 | E13: =SUM(E8:E12) -> 242477408 | F13: =C13+D13+E13 -> 702477408
B16: Control check - Closing equity here must equal Balance Sheet Total Equity: | F16: =IF(ROUND(F13-'Balance Sheet'!D31,0)=0,"TRUE","CHECK!") -> TRUE

Sheet Cash Flow Statement
B2: ABC Trading Limited
B3: Dhaka, Bangladesh
B4: Statement of Cash Flows (Indirect Method)
B5: For the year ended 30-Jun-2026
B7: Particulars | C7: Amount (Taka)
B9: Cash Flows from Operating Activities
B10: Net Profit for the Period | C10: ='Profit & Loss'!$D$32 -> 17477408
B11: Add back: Depreciation (non-cash) | C11: ='Trial Balance'!$K$28-'Trial Balance'!$L$28 -> 79522592
B12: (Increase) / Decrease in Inventories | C12: =-(('Trial Balance'!$K$10-'Trial Balance'!$L$10)-(IFERROR(SUMIF('Opening Balances'!$B$6:$B$22,1100,'Opening Balances'!$D$6:$D$22)-SUMIF('Opening Balances'!$B$6:$B$22,1100,'Opening Balances'!$E$6:$E$22),0))) -> 80000000
B13: (Increase) / Decrease in Accounts Receivable | C13: =-(('Trial Balance'!$K$11-'Trial Balance'!$L$11)-(IFERROR(SUMIF('Opening Balances'!$B$6:$B$22,1110,'Opening Balances'!$D$6:$D$22)-SUMIF('Opening Balances'!$B$6:$B$22,1110,'Opening Balances'!$E$6:$E$22),0))) -> 100000000
B14: (Increase) / Decrease in Advances & Prepayments | C14: =-(('Trial Balance'!$K$12-'Trial Balance'!$L$12)-(IFERROR(SUMIF('Opening Balances'!$B$6:$B$22,1120,'Opening Balances'!$D$6:$D$22)-SUMIF('Opening Balances'!$B$6:$B$22,1120,'Opening Balances'!$E$6:$E$22),0))) -> -25000000
B15: Increase / (Decrease) in Accounts Payable | C15: =('Trial Balance'!$L$16-'Trial Balance'!$K$16)-(IFERROR(SUMIF('Opening Balances'!$B$6:$B$22,2100,'Opening Balances'!$E$6:$E$22)-SUMIF('Opening Balances'!$B$6:$B$22,2100,'Opening Balances'!$D$6:$D$22),0)) -> 50000000
B16: Increase / (Decrease) in Accrued Expenses | C16: =('Trial Balance'!$L$17-'Trial Balance'!$K$17)-(IFERROR(SUMIF('Opening Balances'!$B$6:$B$22,2110,'Opening Balances'!$E$6:$E$22)-SUMIF('Opening Balances'!$B$6:$B$22,2110,'Opening Balances'!$D$6:$D$22),0)) -> 15000000
B17: Increase / (Decrease) in Tax Payable | C17: =('Trial Balance'!$L$19-'Trial Balance'!$K$19)-(IFERROR(SUMIF('Opening Balances'!$B$6:$B$22,2130,'Opening Balances'!$E$6:$E$22)-SUMIF('Opening Balances'!$B$6:$B$22,2130,'Opening Balances'!$D$6:$D$22),0)) -> 2000000
B18: Increase / (Decrease) in Deferred Tax Liability | C18: =('Trial Balance'!$L$15-'Trial Balance'!$K$15)-(IFERROR(SUMIF('Opening Balances'!$B$6:$B$22,2010,'Opening Balances'!$E$6:$E$22)-SUMIF('Opening Balances'!$B$6:$B$22,2010,'Opening Balances'!$D$6:$D$22),0)) -> 5000000
B19: Net Cash from Operating Activities | C19: =SUM(C10:C18) -> 324000000
B21: Cash Flows from Investing Activities
B22: Purchase of Property, Plant & Equipment | C22: =-(('Trial Balance'!$K$6-'Trial Balance'!$L$6)-(IFERROR(SUMIF('Opening Balances'!$B$6:$B$22,1000,'Opening Balances'!$D$6:$D$22)-SUMIF('Opening Balances'!$B$6:$B$22,1000,'Opening Balances'!$E$6:$E$22),0))) -> -85000000
B23: Additions to Capital Work-in-Progress | C23: =-(('Trial Balance'!$K$8-'Trial Balance'!$L$8)-(IFERROR(SUMIF('Opening Balances'!$B$6:$B$22,1020,'Opening Balances'!$D$6:$D$22)-SUMIF('Opening Balances'!$B$6:$B$22,1020,'Opening Balances'!$E$6:$E$22),0))) -> -40000000
B24: (Purchase) / Sale of Long-Term Investments | C24: =-(('Trial Balance'!$K$9-'Trial Balance'!$L$9)-(IFERROR(SUMIF('Opening Balances'!$B$6:$B$22,1030,'Opening Balances'!$D$6:$D$22)-SUMIF('Opening Balances'!$B$6:$B$22,1030,'Opening Balances'!$E$6:$E$22),0))) -> 0
B25: Net Cash used in Investing Activities | C25: =SUM(C22:C24) -> -125000000
B27: Cash Flows from Financing Activities
B28: Proceeds from Share Capital Issued | C28: =('Trial Balance'!$L$20-'Trial Balance'!$K$20)-(IFERROR(SUMIF('Opening Balances'!$B$6:$B$22,3000,'Opening Balances'!$E$6:$E$22)-SUMIF('Opening Balances'!$B$6:$B$22,3000,'Opening Balances'!$D$6:$D$22),0)) -> 10000000
B29: Proceeds / (Repayment) of Long-Term Loan | C29: =('Trial Balance'!$L$14-'Trial Balance'!$K$14)-(IFERROR(SUMIF('Opening Balances'!$B$6:$B$22,2000,'Opening Balances'!$E$6:$E$22)-SUMIF('Opening Balances'!$B$6:$B$22,2000,'Opening Balances'!$D$6:$D$22),0)) -> -100000000
B30: Proceeds / (Repayment) of Short-Term Loan | C30: =('Trial Balance'!$L$18-'Trial Balance'!$K$18)-(IFERROR(SUMIF('Opening Balances'!$B$6:$B$22,2120,'Opening Balances'!$E$6:$E$22)-SUMIF('Opening Balances'!$B$6:$B$22,2120,'Opening Balances'!$D$6:$D$22),0)) -> 20000000
B31: Dividends Paid | C31: =('Changes in Equity'!E11) -> -50000000
B32: Net Cash from Financing Activities | C32: =SUM(C28:C31) -> -120000000
B34: Net Increase / (Decrease) in Cash | C34: =C19+C25+C32 -> 79000000
B35: Cash & Cash Equivalents at Start of Period | C35: =IFERROR(SUMIF('Opening Balances'!$B$6:$B$22,1130,'Opening Balances'!$D$6:$D$22)-SUMIF('Opening Balances'!$B$6:$B$22,1130,'Opening Balances'!$E$6:$E$22),0) -> 60000000
B36: Cash & Cash Equivalents at End of Period | C36: =C34+C35 -> 139000000
B39: Control check - Computed closing cash must equal Balance Sheet Cash: | C39: =IF(ROUND(C36-'Balance Sheet'!D20,0)=0,"TRUE","CHECK!") -> TRUE
